---
title: 错误类型
tags:
  - maidianjiankong
categories:
  - javascript
date: 2021/3/19
permalink: /docs/front-end-base/5418e5b0.html
---

**常见JS执行错误**

1. SyntaxError

> 解析时发生语法错误

```
// 控制台运行
const xx,
```

window.onerror捕获不到SyntxError，一般SyntaxError在构建阶段，甚至本地开发阶段就会被发现。

1. TypeError

> 值不是所期待的类型

```
// 控制台运行
const person = void 0
person.name
```

1. ReferenceError

> 引用未声明的变量

```
// 控制台运行
nodefined
```

1. RangeError

> 当一个值不在其所允许的范围或者集合中

```
(function fn ( ) { fn() })()
```

**网络错误**

1. ResourceError

> 资源加载错误

```
new Image().src = '/remote/image/notdeinfed.png'
```

1. HttpError

> Http请求错误

```
// 控制台运行
fetch('/remote/notdefined', {})
```

**try/catch**

> 能捕获常规运行时错误，语法错误和异步错误不行

```
// 常规运行时错误，可以捕获 ✅
try {
  console.log(notdefined);
} catch(e) {
  console.log('捕获到异常：', e);
}

// 语法错误，不能捕获 ❌
try {
  const notdefined,
} catch(e) {
  console.log('捕获到异常：', e);
}

// 异步错误，不能捕获 ❌
try {
  setTimeout(() => {
    console.log(notdefined);
  }, 0)
} catch(e) {
  console.log('捕获到异常：',e);
}
```

try/catch有它细致处理的优势，但缺点也比较明显。

**window.onerror**

> pure js错误收集，window.onerror，当 JS 运行时错误发生时，window 会触发一个 ErrorEvent 接口的 error 事件。

```
/**
* @param {String} message    错误信息
* @param {String} source    出错文件
* @param {Number} lineno    行号
* @param {Number} colno    列号
* @param {Object} error  Error对象
*/

window.onerror = function(message, source, lineno, colno, error) {
   console.log('捕获到异常：', {message, source, lineno, colno, error});
}
```

先验证下几个错误是否可以捕获。

```
// 常规运行时错误，可以捕获 ✅

window.onerror = function(message, source, lineno, colno, error) {
  console.log('捕获到异常：',{message, source, lineno, colno, error});
}
console.log(notdefined);

// 语法错误，不能捕获 ❌
window.onerror = function(message, source, lineno, colno, error) {
  console.log('捕获到异常：',{message, source, lineno, colno, error});
}
const notdefined,

// 异步错误，可以捕获 ✅
window.onerror = function(message, source, lineno, colno, error) {
  console.log('捕获到异常：',{message, source, lineno, colno, error});
}
setTimeout(() => {
  console.log(notdefined);
}, 0)

// 资源错误，不能捕获 ❌
<script>
  window.onerror = function(message, source, lineno, colno, error) {
  console.log('捕获到异常：',{message, source, lineno, colno, error});
  return true;
}
</script>
<img src="https://yun.tuia.cn/image/kkk.png">
```

window.onerror 不能捕获资源错误怎么办？

**window.addEventListener**

> 当一项资源（如图片或脚本）加载失败，加载资源的元素会触发一个 Event 接口的 error 事件，这些 error 事件不会向上冒泡到 window，但能被捕获。而window.onerror不能监测捕获。

```
// 图片、script、css加载错误，都能被捕获 ✅
<script> window.addEventListener('error', (error) => {
   console.log('捕获到异常：', error);
 }, true) </script>
<img src="https://yun.tuia.cn/image/kkk.png">
<script src="https://yun.tuia.cn/foundnull.js"></script>
<link href="https://yun.tuia.cn/foundnull.css" rel="stylesheet"/>

// new Image错误，不能捕获 ❌
<script> window.addEventListener('error', (error) => {
    console.log('捕获到异常：', error);
  }, true) </script>
<script> new Image().src = 'https://yun.tuia.cn/image/lll.png' </script>

// fetch错误，不能捕获 ❌
<script> window.addEventListener('error', (error) => {
    console.log('捕获到异常：', error);
  }, true) </script>
<script> fetch('https://tuia.cn/test') </script>
```

new Image运用的比较少，可以单独自己处理自己的错误。

但通用的fetch怎么办呢，fetch返回Promise，但Promise的错误不能被捕获，怎么办呢？

**Promise错误**

1. 普通Promise错误

> try/catch不能捕获Promise中的错误

```
// try/catch 不能处理 JSON.parse 的错误，因为它在 Promise 中
try {
  new Promise((resolve,reject) => {
    JSON.parse('')
    resolve();
  })
} catch(err) {
  console.error('in try catch', err)
}

// 需要使用catch方法
new Promise((resolve,reject) => {
  JSON.parse('')
  resolve();
}).catch(err => {
  console.log('in catch fn', err)
})
```

1. async错误

> try/catch不能捕获async包裹的错误

```
const getJSON = async () => {
  throw new Error('inner error')
}

// 通过try/catch处理
const makeRequest = async () => {
    try {
        // 捕获不到
        JSON.parse(getJSON());
    } catch (err) {
        console.log('outer', err);
    }
};

try {
    // try/catch不到
    makeRequest()
} catch(err) {
    console.error('in try catch', err)
}

try {
    // 需要await，才能捕获到
    await makeRequest()
} catch(err) {
    console.error('in try catch', err)
}
```

1. import chunk错误

> import其实返回的也是一个promise，因此使用如下两种方式捕获错误

```
// Promise catch方法
import(/* webpackChunkName: "incentive" */'./index').then(module => {
    module.default()
}).catch((err) => {
    console.error('in catch fn', err)
})

// await 方法，try catch
try {
    const module = await import(/* webpackChunkName: "incentive" */'./index');
    module.default()
} catch(err) {
    console.error('in try catch', err)
}
```

小结：全局捕获Promise中的错误

以上三种其实归结为Promise类型错误，可以通过unhandledrejection捕获

```
// 全局统一处理Promise
window.addEventListener("unhandledrejection", function(e){
  console.log('捕获到异常：', e);
});
fetch('https://tuia.cn/test')
```

为了防止有漏掉的 Promise 异常，可通过unhandledrejection用来全局监听Uncaught Promise Error。

**React错误**

> react 通过componentDidCatch，声明一个错误边界的组件

```
class ErrorBoundary extends React.Component {
  constructor(props) {
    super(props);
    this.state = { hasError: false };
  }

  static getDerivedStateFromError(error) {
    // 更新 state 使下一次渲染能够显示降级后的 UI
    return { hasError: true };
  }

  componentDidCatch(error, errorInfo) {
    // 你同样可以将错误日志上报给服务器
    logErrorToMyService(error, errorInfo);
  }

  render() {
    if (this.state.hasError) {
      // 你可以自定义降级后的 UI 并渲染
      return <h1>Something went wrong.</h1>;
    }

    return this.props.children;
  }
}

class App extends React.Component {

  render() {
    return (
    <ErrorBoundary>
      <MyWidget />
    </ErrorBoundary>
    )
  }
}
```

但error boundaries并不会捕捉以下错误：React事件处理，异步代码，error boundaries自己抛出的错误
